<robot name="6DoF" version="1.0">
  <joint name="Joint1" type="revolute">
    <limit lower="0.00000000" upper="3.14199996" effort="87" velocity="2.3925"/>
    <origin rpy="0.00000000 0.00000000 -1.57079637" xyz="0.00000000 0.00000000 0.1324"/>
    <parent link="base_link"/>
    <child link="servo1_servo2_link"/>
    <axis xyz="0.00000000 0.00000000 1.00000000"/>
  </joint>

  <joint name="Joint2" type="revolute">
    <limit lower="0.00000000" upper="3.14000010" effort="87" velocity="2.3925"/>
    <origin rpy="-1.57079637 0.00000000 0.00000000" xyz="0.00000000 0.00000000 0.012"/>
    <parent link="servo1_servo2_link"/>
    <child link="servo2_servo3_link"/>
    <axis xyz="0.00000000 0.00000000 1.00000000"/>
  </joint>

  <joint name="Joint3" type="revolute">
    <limit lower="0.00000000" upper="3.14000010" effort="87" velocity="2.3925"/>
    <origin rpy="3.14159265 0.00000000 3.14159257" xyz="-0.104538 0.00000000 -0.00000006"/>
    <parent link="servo2_servo3_link"/>
    <child link="servo3_servo4_link"/>
    <axis xyz="0.00000000 0.00000000 1.00000000"/>
  </joint>
  
  <joint name="Joint4" type="revolute">
    <limit lower="0.00000000" upper="3.14000010" effort="87" velocity="2.3925"/>
    <origin rpy="3.14159257 -0.00000012 0.00000000" xyz="-0.008356 -0.101547 0.00001584"/>
    <parent link="servo3_servo4_link"/>
    <child link="servo4_servo5_link"/>
    <axis xyz="0.00000000 0.00000000 1.00000000"/>
  </joint>

  <joint name="Joint5" type="revolute">
    <limit lower="0.00000000" upper="3.14000010" effort="87" velocity="2.3925"/>
    <origin rpy="-1.57079628 -0.00000009 0.00000009" xyz="-0.028738 0.047654 0.00000208"/>
    <parent link="servo4_servo5_link"/>
    <child link="servo5_servo6_link"/>
    <axis xyz="0.00000000 0.00000000 1.00000000"/>
  </joint>
  
  

  <joint name="left_hand_finger_joint" type="prismatic">
        <parent link="servo5_servo6_link" />
        <child link="left_finger_link" />
        <origin rpy="1.57079637 0.00000000 -3.14159257" xyz="0.000101 -0.000827 0.057582" />
        <axis xyz="0 0 1" />
        <limit effort="20" lower="0.0" upper="0.014" velocity="0.2" />
  </joint>
  <joint name="right_hand_finger_joint" type="prismatic">
        <parent link="servo5_servo6_link" />
        <child link="right_finger_link" />
        <origin rpy="1.57079637 0.00000000 -3.14159257" xyz="0.000101 -0.000827 0.057582" />
        <axis xyz="0 0 -1" />
        <limit effort="20" lower="0.0" upper="0.014" velocity="0.2" />
        <mimic joint="left_hand_finger_joint" />
  </joint>
  
  
  <link name="base_link">
    <collision name="base_collision">
      <origin rpy="1.57079625 -0.00000000 -3.14159250" xyz="0.029 -0.036 0.06715160"/>
      <geometry>
        <mesh filename="package://moveit_resources_dragon_description/meshes/stl/base.stl" scale="0.001 0.001 0.001"/>
      </geometry>
    </collision>
    <visual name="base">
      <origin rpy="1.57079633 -0.00000000 -3.14159257" xyz="0.0285 -0.0355 0.06715160"/>
      <geometry>
        <mesh filename="package://moveit_resources_dragon_description/meshes/stl/base.stl" scale="0.001 0.001 0.001"/>
      </geometry>
      <material name="Red">
        <color rgba="1 0 0 1"/>
      </material>
    </visual>
  </link> 
  
  <link name="servo1_servo2_link">
    <collision name="Joint1_collision">
      <origin rpy="0.00000000 0.00000000 -1.57079625" xyz="-0.00030 0.0074 -0.000062"/>
      <geometry>
        <mesh filename="package://moveit_resources_dragon_description/meshes/stl/joint1.stl" scale="0.001 0.001 0.001"/>
      </geometry>
    </collision>
    <visual name="Joint1">
      <origin rpy="0.00000000 0.00000000 -1.57079625" xyz="-0.00030 0.0074 -0.000062"/>
      <geometry>
        <mesh filename="package://moveit_resources_dragon_description/meshes/stl/joint1.stl" scale="0.001 0.001 0.001"/>
      </geometry>
      <material name="Green">
        <color rgba="0 1 0 1"/>
      </material>
    </visual>
  </link>
  
  
  
  <link name="servo2_servo3_link">
    <collision name="joint2_collision">
      <origin rpy="1.57079645 0.00000004 -1.57079637" xyz="-0.001 0.000 0.021"/>
      <geometry>
        <mesh filename="package://moveit_resources_dragon_description/meshes/stl/joint2.stl" scale="0.001 0.001 0.001"/>
      </geometry>
    </collision>
    <visual name="joint2">
      <origin rpy="1.57079645 0.00000004 -1.57079637" xyz="-0.001 0.000 0.021"/>
      <geometry>
        <mesh filename="package://moveit_resources_dragon_description/meshes/stl/joint2.stl" scale="0.001 0.001 0.001"/>
      </geometry>
      <material name="Blue">
        <color rgba="0 0 1 1"/>
      </material>
    </visual>
  </link>
  
  
  
  <link name="servo3_servo4_link">
    <collision name="Joint3_collision">
      <origin rpy="3.14159249 0.00000004 1.57079620" xyz="-0.000421 0.000 -0.025"/>
      <geometry>
        <mesh filename="package://moveit_resources_dragon_description/meshes/stl/joint3.stl" scale="0.001 0.001 0.001"/>
      </geometry>
    </collision>
    <visual name="Joint3">
      <origin rpy="3.14159249 0.00000004 1.57079620" xyz="-0.000421 0.000 -0.025"/>
      <geometry>
        <mesh filename="package://moveit_resources_dragon_description/meshes/stl/joint3.stl" scale="0.001 0.001 0.001"/>
      </geometry>
      <material name="Yellow">
        <color rgba="1 1 0 1"/>
      </material>
    </visual>
  </link>
  
  
  <link name="servo4_servo5_link">
    <collision name="Joint4_collision">
      <origin rpy="-0.00000009 0.00000000 -3.14159256" xyz="0.00 0.01 -0.021"/>
      <geometry>
        <mesh filename="package://moveit_resources_dragon_description/meshes/stl/joint4.stl" scale="0.001 0.001 0.001"/>
      </geometry>
    </collision>
    <visual name="Joint4">
      <origin rpy="-0.00000009 0.00000000 -3.14159257" xyz="0.000 0.01 -0.021"/>
      <geometry>
        <mesh filename="package://moveit_resources_dragon_description/meshes/stl/joint4.stl" scale="0.001 0.001 0.001"/>
      </geometry>
      <material name="Cyan">
        <color rgba="0 1 1 1"/>
      </material>
    </visual>
  </link>


  <link name="servo5_servo6_link">
    <collision name="Gripper_palm_collision">
      <origin rpy="1.57079637 0.00000000 -3.14159257" xyz="0.0018 -0.01 0.000336"/>
      <geometry>
        <mesh filename="package://moveit_resources_dragon_description/meshes/stl/gripper_palm.stl" scale="0.001 0.001 0.001"/>
      </geometry>
    </collision>
    <visual name="Gripper_palm">
      <origin rpy="1.57079637 0.00000000 -3.14159257" xyz="0.0018 -0.01 0.000336"/>
      <geometry>
        <mesh filename="package://moveit_resources_dragon_description/meshes/stl/gripper_palm.stl" scale="0.001 0.001 0.001"/>
      </geometry>
      <material name="Magenta">
        <color rgba="1 0 1 1"/>
      </material>
    </visual>
  </link>


   <link name="left_finger_link">
    <collision name="left_finger_collision">
      <origin rpy="-1.57079633 1.57079626 0.00000000" xyz="0.003360 -0.001577 0.007136"/>
      <geometry>
        <mesh filename="package://moveit_resources_dragon_description/meshes/stl/left_finger.stl" scale="0.001 0.001 0.001"/>
      </geometry>
    </collision>
    
    <visual name="left_finger">
      <origin rpy="-1.57079633 1.57079626 0.00000000" xyz="0.003360 -0.001577 0.007136"/>
      <geometry>
        <mesh filename="package://moveit_resources_dragon_description/meshes/stl/left_finger.stl" scale="0.001 0.001 0.001"/>
      </geometry>
      <material name="Green">
        <color rgba="0 1 0 1"/>
      </material>
    </visual>
   </link>

   <link name="right_finger_link">
    <collision name="right_finger_collision">
      <origin rpy="-1.57079633 1.57079626 0.00000000" xyz="0.003360 -0.001585 -0.006823"/>
      <geometry>
        <mesh filename="package://moveit_resources_dragon_description/meshes/stl/right_finger.stl" scale="0.001 0.001 0.001"/>
      </geometry>
    </collision>
    <visual name="right_finger">
      <origin rpy="1.83292169 1.57079616 -2.87946729" xyz="0.003360 -0.001585 -0.006823"/>
      <geometry>
        <mesh filename="package://moveit_resources_dragon_description/meshes/stl/right_finger.stl" scale="0.001 0.001 0.001"/>
      </geometry>
      <material name="Green">
        <color rgba="0 1 0 1"/>
      </material>
    </visual>
  </link>
</robot>

