<robot name="twolink_model" version="1.0">
  <joint name="Fingers_link_joint" type="fixed">
    <origin rpy="-1.57080 0.00000 0.00000" xyz="1.21973 28.89346 -1.50631"/>
    <parent link="servo5_servo6_link"/>
    <child link="Fingers_link"/>
  </joint>
  <joint name="new_link_joint" type="revolute">
    <limit lower="0.00000" upper="3.14200" effort="0.00000" velocity="0.00000"/>
    <origin rpy="-1.57080 0.00000 0.00000" xyz="26.35443 11.75584 -52.58681"/>
    <parent link="servo4_servo5_link"/>
    <child link="servo5_servo6_link"/>
    <axis xyz="0.00000 1.00000 0.00000"/>
  </joint>
  <joint name="servo1_servo2_link_joint" type="revolute">
    <limit lower="0.00000" upper="3.14000" effort="0.00000" velocity="0.00000"/>
    <origin rpy="0.00000 0.00000 -1.57080" xyz="-7.47051 -9.33603 88.85034"/>
    <parent link="base_link"/>
    <child link="servo1_servo2_link"/>
    <axis xyz="0.00000 0.00000 1.00000"/>
  </joint>
  <joint name="servo2_servo3_link.000_joint" type="revolute">
    <limit lower="0.00000" upper="3.14200" effort="0.00000" velocity="0.00000"/>
    <origin rpy="1.57080 -0.00000 -1.57080" xyz="-24.86075 -1.88139 15.44978"/>
    <parent link="servo1_servo2_link"/>
    <child link="servo2_servo3_link.000"/>
    <axis xyz="0.00000 1.00000 0.00000"/>
  </joint>
  <joint name="servo3_servo4_link_joint" type="revolute">
    <limit lower="0.00000" upper="3.14200" effort="0.00000" velocity="0.00000"/>
    <origin rpy="-1.57080 0.00000 3.14159" xyz="102.73749 -0.41143 -0.50667"/>
    <parent link="servo2_servo3_link.000"/>
    <child link="servo3_servo4_link"/>
    <axis xyz="0.00000 1.00000 0.00000"/>
  </joint>
  <joint name="servo4_servo5_link_joint" type="revolute">
    <limit lower="0.00000" upper="3.14200" effort="0.00000" velocity="0.00000"/>
    <origin rpy="-0.00000 0.00000 0.00000" xyz="8.58900 2.00931 -101.83701"/>
    <parent link="servo3_servo4_link"/>
    <child link="servo4_servo5_link"/>
    <axis xyz="0.00000 1.00000 0.00000"/>
  </joint>
  <link name="Fingers_link">
    <collision name="left_finger_collision">
      <origin rpy="0.00000 0.00000 1.57080" xyz="4.44363 -8.42355 22.07001"/>
      <geometry>
        <mesh filename="../meshes/stl/left_finger.stl" scale="1.00000 1.00000 1.00000"/>
      </geometry>
    </collision>
    <collision name="right_finger_collision">
      <origin rpy="0.00000 0.00085 1.57080" xyz="4.52390 5.44889 22.18753"/>
      <geometry>
        <mesh filename="../meshes/stl/right_finger.stl" scale="1.00000 1.00000 1.00000"/>
      </geometry>
    </collision>
    <visual name="left_finger">
      <origin rpy="0.00000 0.00000 1.57080" xyz="4.52772 -8.41627 22.20316"/>
      <geometry>
        <mesh filename="../meshes/stl/left_finger.stl" scale="1.00000 1.00000 1.00000"/>
      </geometry>
    </visual>
    <visual name="right_finger">
      <origin rpy="0.00000 0.00085 1.57080" xyz="4.52772 5.54306 22.19449"/>
      <geometry>
        <mesh filename="../meshes/stl/right_finger.stl" scale="1.00000 1.00000 1.00000"/>
      </geometry>
    </visual>
  </link>
  <link name="base_link">
    <collision name="base_collision">
      <origin rpy="-1.57080 1.57080 0.00000" xyz="-42.82745 18.91014 27.02244"/>
      <geometry>
        <mesh filename="../meshes/stl/base.stl" scale="-1.00000 -1.00000 -1.00000"/>
      </geometry>
    </collision>
    <visual name="base">
      <origin rpy="1.57080 1.57080 0.00000" xyz="-42.81242 18.94182 27.00017"/>
      <geometry>
        <mesh filename="../meshes/stl/base.stl" scale="-1.00000 -1.00000 -1.00000"/>
      </geometry>
    </visual>
  </link>
  <link name="servo1_servo2_link">
    <collision name="Joint1_collision">
      <origin rpy="0.00000 0.00000 -0.00000" xyz="0.28388 7.43921 3.06186"/>
      <geometry>
        <mesh filename="../meshes/stl/joint1.stl" scale="1.00000 1.00000 1.00000"/>
      </geometry>
    </collision>
    <visual name="Joint1">
      <origin rpy="0.00000 0.00000 -0.00000" xyz="0.36541 7.45386 3.06097"/>
      <geometry>
        <mesh filename="../meshes/stl/joint1.stl" scale="1.00000 1.00000 1.00000"/>
      </geometry>
    </visual>
  </link>
  <link name="servo2_servo3_link.000">
    <collision name="joint2_collision">
      <origin rpy="1.57080 0.00000 -1.57080" xyz="102.73060 -0.09144 -4.63736"/>
      <geometry>
        <mesh filename="../meshes/stl/joint2.stl" scale="1.00000 1.00000 1.00000"/>
      </geometry>
    </collision>
    <visual name="joint2">
      <origin rpy="1.57080 -0.00000 1.57080" xyz="0.00939 0.02306 -4.63636"/>
      <geometry>
        <mesh filename="../meshes/stl/joint2.stl" scale="1.00000 1.00000 1.00000"/>
      </geometry>
    </visual>
  </link>
  <link name="servo3_servo4_link">
    <collision name="Joint3_collision">
      <origin rpy="-0.00000 -1.57080 1.57080" xyz="0.08767 -0.03848 0.11838"/>
      <geometry>
        <mesh filename="../meshes/stl/joint3.stl" scale="1.00000 1.00000 1.00000"/>
      </geometry>
    </collision>
    <visual name="Joint3">
      <origin rpy="1.57080 -1.57080 0.00000" xyz="0.01082 0.20425 0.00879"/>
      <geometry>
        <mesh filename="../meshes/stl/joint3.stl" scale="1.00000 1.00000 1.00000"/>
      </geometry>
    </visual>
  </link>
  <link name="servo4_servo5_link">
    <collision name="Joint4_collision">
      <origin rpy="1.57080 -0.00000 0.00000" xyz="-0.62083 43.63789 -9.77660"/>
      <geometry>
        <mesh filename="../meshes/stl/joint4.stl" scale="1.00000 1.00000 1.00000"/>
      </geometry>
    </collision>
    <visual name="Joint4">
      <origin rpy="1.57080 0.00000 0.00000" xyz="-0.58103 43.63519 -9.75771"/>
      <geometry>
        <mesh filename="../meshes/stl/joint4.stl" scale="1.00000 1.00000 1.00000"/>
      </geometry>
    </visual>
  </link>
  <link name="servo5_servo6_link">
    <collision name="Gripper_palm_collision">
      <origin rpy="0.00000 0.00000 -0.00000" xyz="0.00886 -4.29803 -0.01584"/>
      <geometry>
        <mesh filename="../meshes/stl/gripper_palm.stl" scale="1.00000 1.00000 1.00000"/>
      </geometry>
    </collision>
    <visual name="Gripper_palm">
      <origin rpy="0.00000 0.00000 -0.00000" xyz="-0.06979 -4.34268 0.02743"/>
      <geometry>
        <mesh filename="../meshes/stl/gripper_palm.stl" scale="1.00000 1.00000 1.00000"/>
      </geometry>
    </visual>
  </link>
</robot>