<?xml version="1.0" ?>
<!-- =================================================================================== -->
<!-- |    This document was autogenerated by xacro from /home/robot/ws_moveit2/install/myrobot_moveit_config/share/myrobot_moveit_config/config/my_robot.urdf.xacro | -->
<!-- |    EDITING THIS FILE BY HAND IS NOT RECOMMENDED                                 | -->
<!-- =================================================================================== -->
<robot name="my_robot">
  <material name="grey">
    <color rgba="0.5 0.5 0.5 1.0"/>
  </material>
  <material name="red">
    <color rgba="1.0 0.0 0.0 1.0"/>
  </material>
  <material name="green">
    <color rgba="0.0 1.0 0.0 1.0"/>
  </material>
  <material name="blue">
    <color rgba="0.0 0.0 1.0 1.0"/>
  </material>
  <material name="yellow">
    <color rgba="1.0 1.0 0.0 1.0"/>
  </material>
  <material name="cyan">
    <color rgba="0.0 1.0 1.0 1.0"/>
  </material>
  <material name="magenta">
    <color rgba="1.0 0.0 1.0 1.0"/>
  </material>
  <!-- Links definations -->
  <!-- FOOTPRINT -->
  <link name="arm_base_footprint"/>
  <!-- BASE LINK STATIC -->
  <link name="arm_base_link">
    <visual>
      <geometry>
        <box size="0.088 0.09 0.105"/>
      </geometry>
      <origin rpy="0 0 0" xyz="0 0 0.0525"/>
      <material name="grey"/>
    </visual>
    <collision>
      <geometry>
        <box size="0.088 0.09 0.105"/>
      </geometry>
      <origin rpy="0 0 0" xyz="0 0 0.0525"/>
    </collision>
    <inertial>
      <origin rpy="0 0 0" xyz="0 0 0.0525"/>
      <mass value="0.5"/>
      <inertia ixx="0.0031281666666666662" ixy="0" ixz="0" iyy="0.002640666666666666" iyz="0" izz="0.0031874999999999994"/>
    </inertial>
  </link>
  <!-- LINK1 This is between first servos1 and 2 -->
  <link name="link1">
    <visual>
      <geometry>
        <box size="0.0254 0.05842 0.0254"/>
      </geometry>
      <origin rpy="0 0 0" xyz="0 0.023368 0.0127"/>
      <material name="green"/>
    </visual>
    <collision>
      <geometry>
        <box size="0.0254 0.05842 0.0254"/>
      </geometry>
      <origin rpy="0 0 0" xyz="0 0.023368 0.0127"/>
    </collision>
    <inertial>
      <origin rpy="0 0 0" xyz="0 0.023368 0.0127"/>
      <mass value="0.5"/>
      <inertia ixx="0.0002150533333333333" ixy="0" ixz="0" iyy="0.0006763427333333333" iyz="0" izz="0.0006763427333333333"/>
    </inertial>
  </link>
  <!-- LINK2 This is between servos2 and 3 -->
  <link name="link2">
    <visual>
      <geometry>
        <box size="0.0254 0.05842 0.12"/>
      </geometry>
      <origin rpy="0 -1.5708 1.5708" xyz="-0.02921 0.048 0.0127"/>
      <material name="blue"/>
    </visual>
    <collision>
      <geometry>
        <box size="0.0254 0.05842 0.08399999999999999"/>
      </geometry>
      <origin rpy="0 -1.5708 1.5708" xyz="-0.02921 0.048 0.0127"/>
    </collision>
    <inertial>
      <origin rpy="0 -1.5708 1.5708" xyz="-0.02921 0.048 0.0127"/>
      <mass value="0.5"/>
      <inertia ixx="0.0025075266666666667" ixy="0" ixz="0" iyy="0.0006763427333333333" iyz="0" izz="0.0029688160666666665"/>
    </inertial>
  </link>
  <!-- LINK3 This is between servos3 and 4 -->
  <link name="link3">
    <visual>
      <geometry>
        <box size="0.0254 0.05842 0.1016"/>
      </geometry>
      <origin rpy="0 0 1.5708" xyz="0.02921 0 -0.0508"/>
      <material name="yellow"/>
    </visual>
    <collision>
      <geometry>
        <box size="0.0254 0.05842 0.1016"/>
      </geometry>
      <origin rpy="0 0 1.5708" xyz="0.02921 0 -0.0508"/>
    </collision>
    <inertial>
      <origin rpy="0 0 1.5708" xyz="0.02921 0 -0.0508"/>
      <mass value="0.5"/>
      <inertia ixx="0.0018279533333333334" ixy="0" ixz="0" iyy="0.0006763427333333333" iyz="0" izz="0.0022892427333333332"/>
    </inertial>
  </link>
  <!-- LINK4 This is between servos4 and 5 -->
  <link name="link4">
    <visual>
      <geometry>
        <box size="0.0508 0.05715 0.0635"/>
      </geometry>
      <origin rpy="1.5708 0 0" xyz="0.028575 0.03175 0"/>
      <material name="cyan"/>
    </visual>
    <collision>
      <geometry>
        <box size="0.0508 0.05715 0.0635"/>
      </geometry>
      <origin rpy="1.5708 0 0" xyz="0.028575 0.03175 0"/>
    </collision>
    <inertial>
      <origin rpy="1.5708 0 0" xyz="0.028575 0.03175 0"/>
      <mass value="0.5"/>
      <inertia ixx="0.0011021483333333332" ixy="0" ixz="0" iyy="0.0009744604166666666" iyz="0" izz="0.0012163954166666668"/>
    </inertial>
  </link>
  <!-- LINK5 This is between servos5 and 6 -->
  <link name="link5">
    <visual>
      <geometry>
        <box size="0.0254 0.03302 0.1016"/>
      </geometry>
      <origin rpy="0 0 0" xyz="0 0.012700000000000001 0"/>
      <material name="magenta"/>
    </visual>
    <collision>
      <geometry>
        <box size="0.0254 0.03302 0.1016"/>
      </geometry>
      <origin rpy="0 0 0" xyz="0 0.012700000000000001 0"/>
    </collision>
    <inertial>
      <origin rpy="0 0 0" xyz="0 0.012700000000000001 0"/>
      <mass value="0.5"/>
      <inertia ixx="0.0018279533333333334" ixy="0" ixz="0" iyy="0.0002892467333333333" iyz="0" izz="0.0019021467333333333"/>
    </inertial>
  </link>
  <!-- hand This is between servos5 and 6 -->
  <link name="hand">
    <visual>
      <geometry>
        <box size="0.1016 0.0508 0.0254"/>
      </geometry>
      <origin rpy="0 0 0" xyz="0 0.0508 0"/>
      <material name="red"/>
    </visual>
    <collision>
      <geometry>
        <box size="0.1016 0.0508 0.0254"/>
      </geometry>
      <origin rpy="0 0 0" xyz="0 0.0508 0"/>
    </collision>
    <inertial>
      <origin rpy="0 0 0" xyz="0 0 0"/>
      <mass value="0.5"/>
      <inertia ixx="0.0005376333333333333" ixy="0" ixz="0" iyy="0.0008602133333333332" iyz="0" izz="0.0005376333333333333"/>
    </inertial>
  </link>
  <link name="hand_leftfinger">
    <visual>
      <geometry>
        <box size="0.0127 0.0508 0.0254"/>
      </geometry>
      <origin rpy="0 0 0" xyz="-0.0254 0.1016 0"/>
      <material name="yellow"/>
    </visual>
    <collision>
      <geometry>
        <box size="0.0127 0.0508 0.0254"/>
      </geometry>
      <origin rpy="0 0 0" xyz="-0.0254 0.1016 0"/>
    </collision>
    <inertial>
      <origin rpy="0 0 0" xyz="0 0 0"/>
      <mass value="0.5"/>
      <inertia ixx="0.00013440833333333333" ixy="0" ixz="0" iyy="0.00045698833333333334" iyz="0" izz="0.0005376333333333333"/>
    </inertial>
  </link>
  <link name="hand_rightfinger">
    <visual>
      <geometry>
        <box size="0.0127 0.0508 0.0254"/>
      </geometry>
      <origin rpy="0 0 0" xyz="0.0254 0.1016 0"/>
      <material name="yellow"/>
    </visual>
    <collision>
      <geometry>
        <box size="0.0127 0.0508 0.0254"/>
      </geometry>
      <origin rpy="0 0 0" xyz="0.0254 0.1016 0"/>
    </collision>
    <inertial>
      <origin rpy="0 0 0" xyz="0 0 0"/>
      <mass value="0.5"/>
      <inertia ixx="0.00013440833333333333" ixy="0" ixz="0" iyy="0.00045698833333333334" iyz="0" izz="0.0005376333333333333"/>
    </inertial>
  </link>
  <!--JOINTS-->
  <!--JOINT FROM FOOTPRINT TO BASE-->
  <joint name="arm_base_joint" type="fixed">
    <parent link="arm_base_footprint"/>
    <child link="arm_base_link"/>
    <origin rpy="0 0 0" xyz="0 0 0"/>
  </joint>
  <!--JOINT FROM BASE TO LINK1-->
  <joint name="base_link1_joint" type="revolute">
    <parent link="arm_base_link"/>
    <child link="link1"/>
    <origin rpy="0 0 0" xyz="0 0 0.105"/>
    <axis xyz="0 0 1"/>
    <limit effort="100" lower="0" upper="3.141592653589793" velocity="100"/>
    <dynamic damping="0.1" friction="0.05"/>
  </joint>
  <!--JOINT FROM LINK1 TO LINK2-->
  <joint name="link1_link2_joint" type="revolute">
    <parent link="link1"/>
    <child link="link2"/>
    <origin rpy="0 0 0" xyz="0.02921 0 0.0254"/>
    <axis xyz="1 0 0"/>
    <limit effort="100" lower="0" upper="3.141592653589793" velocity="100"/>
    <dynamic damping="0.1" friction="0.05"/>
  </joint>
  <!--JOINT FROM LINK2 TO LINK3-->
  <joint name="link2_link3_joint" type="revolute">
    <parent link="link2"/>
    <child link="link3"/>
    <origin rpy="0 0 0" xyz="-0.05842 0.1016 0.0254"/>
    <axis xyz="1 0 0"/>
    <limit effort="100" lower="0" upper="3.141592653589793" velocity="100"/>
    <dynamic damping="0.1" friction="0.05"/>
  </joint>
  <!--JOINT FROM LINK3 TO LINK4-->
  <joint name="link3_link4_joint" type="revolute">
    <parent link="link3"/>
    <child link="link4"/>
    <origin rpy="0 0 0" xyz="0 0 -0.1016"/>
    <axis xyz="-1 0 0"/>
    <limit effort="100" lower="0" upper="3.141592653589793" velocity="100"/>
    <dynamic damping="0.1" friction="0.05"/>
  </joint>
  <!--JOINT FROM LINK4 TO LINK5-->
  <joint name="link4_link5_joint" type="revolute">
    <parent link="link4"/>
    <child link="link5"/>
    <origin rpy="0 0 0" xyz="0.028575 0.06985 0"/>
    <axis xyz="0 1 0"/>
    <limit effort="100" lower="0" upper="3.141592653589793" velocity="100"/>
    <dynamic damping="0.1" friction="0.05"/>
  </joint>
  <!--JOINT FROM LINK5 TO HAND-->
  <joint name="link5_hand_joint" type="fixed">
    <parent link="link5"/>
    <child link="hand"/>
    <origin rpy="0 0 0" xyz="0 0 0"/>
  </joint>
  <joint name="hand_finger_joint1" type="prismatic">
    <parent link="hand"/>
    <child link="hand_leftfinger"/>
    <origin rpy="0 0 0" xyz="0 0 0"/>
    <axis xyz="1 0 0"/>
    <limit effort="20" lower="0.0" upper="0.019" velocity="0.2"/>
  </joint>
  <joint name="hand_finger_joint2" type="prismatic">
    <parent link="hand"/>
    <child link="hand_rightfinger"/>
    <origin rpy="0 0 0" xyz="0 0 0"/>
    <axis xyz="-1 0 0"/>
    <limit effort="20" lower="0.0" upper="0.019" velocity="0.2"/>
    <mimic joint="hand_finger_joint1"/>
  </joint>
  <ros2_control name="FakeSystem" type="system">
    <hardware>
      <!-- By default, set up controllers for simulation. This won't work on real hardware -->
      <plugin>mock_components/GenericSystem</plugin>
    </hardware>
    <joint name="base_link1_joint">
      <command_interface name="position"/>
      <state_interface name="position">
        <param name="initial_value">0</param>
      </state_interface>
      <state_interface name="velocity"/>
    </joint>
    <joint name="link1_link2_joint">
      <command_interface name="position"/>
      <state_interface name="position">
        <param name="initial_value">0</param>
      </state_interface>
      <state_interface name="velocity"/>
    </joint>
    <joint name="link2_link3_joint">
      <command_interface name="position"/>
      <state_interface name="position">
        <param name="initial_value">0</param>
      </state_interface>
      <state_interface name="velocity"/>
    </joint>
    <joint name="link3_link4_joint">
      <command_interface name="position"/>
      <state_interface name="position">
        <param name="initial_value">0</param>
      </state_interface>
      <state_interface name="velocity"/>
    </joint>
    <joint name="link4_link5_joint">
      <command_interface name="position"/>
      <state_interface name="position">
        <param name="initial_value">0</param>
      </state_interface>
      <state_interface name="velocity"/>
    </joint>
    <joint name="hand_finger_joint1">
      <command_interface name="position"/>
      <state_interface name="position">
        <param name="initial_value">0</param>
      </state_interface>
      <state_interface name="velocity"/>
    </joint>
  </ros2_control>
</robot>
